Workbook
Name cadena: [1]Listas!$I$3:$I$6
Name coso: [1]Listas!$B$17:$B$24
Name Diseño: [1]Listas!$B$43:$B$49
Name efectividad: [1]Listas!$B$52:$B$57
Name frecuencia: [1]Listas!$B$65:$B$76
Name macroproceso: [1]Listas!$K$3:$K$27
Name macroprocesoall: [1]Listas!$N$3:$N$134
Name naturaleza: [1]Listas!$B$60:$B$62
Name proceso: [1]Listas!$O$3:$O$134
Name respuesta: [1]Listas!$B$26:$B$27
Name tipo: [1]Listas!$B$79:$B$81
Name valor: [1]Listas!$J$3:$J$27

Sheet RACM
K1: r
L2: Completar parcialmente | Q2: No completar de momento
L3: Responsabilidad del Control | N3: Caracteristicas del Control | Q3: Factores de Riesgo | T3: Factores de Estructura de Control | Y3: Clasificación del Control | AB3: Diseño del Control | AH3: Operatividad del control | AT3: Dictamen Anual
B4: Componente | C4: Principio | D4: Enfoque Prov, 209 | E4: ID del Riesgo | F4: Tipologia del Riesgo (El Tipo) | G4: Descripción del Riesgo | H4: ID Control | I4: Actividad de Control Ron Santa Teresa Vigente | J4: Propuesta de Redacción de Control Interno | K4: Cumple Prov, 209 | L4: Depedencia Responsable | M4: Responsable | N4: Tipo | O4: Naturaleza | P4: Frecuencia | Q4: ¿El control mitiga riesgos de fraude interno y externo? | R4: ¿El control es mitigante de al menos un riesgo que sea clasificado como "medio" y/o “alto”? | S4: ¿El control por sí sólo es mitigante de varios riesgos? | T4: ¿El control es esencial para el cumplimiento de los objetivos de la actividad? | U4: ¿La omisión del control puede afectar el objetivo de información definido en COSO 2013? | V4: ¿La omisión del control puede afectar el objetivo operativo definido en COSO 2013? | W4: ¿La omisión del control puede afectar el objetivo de cumplimiento definido en COSO 2013? | X4: ¿El control es clasificado como detectivo? | Y4: Sub-Ponderación | Z4: Ponderación del control | AA4: Control Clave (S/N) metodología | AB4: 1era entrada | AC4: Referencia de Recorrido 1era entrada | AD4: 2da entrada | AE4: Referencia de Recorrido 2da entrada | AF4: 3ra entrada | AG4: Referencia de Recorrido 3ra entrada | AH4: 1era entrada | AI4: Hallazgos / Oportunidad de Mejora | AJ4: Severidad de la inefectividad | AK4: Referencia de pruebas 1era entrada | AL4: 2da entrada | AM4: Hallazgos / Oportunidad de Mejora | AN4: Severidad de la inefectividad | AO4: Referencia de pruebas 2da entrada | AP4: 3era entrada | AQ4: Hallazgos / Oportunidad de Mejora | AR4: Severidad de la inefectividad | AS4: Referencia de pruebas 3era entrada | AT4: Estatus del control | AU4: Comentarios
B5: PCLCFT. 01 Estructura | C5: Organigrama: Estructura del Sistema Integral de PCLCFT | D5: Artículo 15: Conformación del SIAR LCFTFPADM: 1. La Junta Directiva o el Órgano que ejerza fundan equivalente; 2. El presidente del sujeto obligado que ejerza función equivalente. 3. El odicial de cumplimiento. 4. La Unidad de AR LC/FI'/FPADM v Otros Ilícitos; 5. El Responsable de Cumplimiento designado en cada área sensible de riesgo 6. Los Responsables de primera línea de contacto. | E5: R01 | H5: PCLCFT. 01 | I5: Se realizó la revisión de la estructura de PCLCFTPADM con base a la Prov 209 y GAFILAT con el fin de validar que la misma cumpliera con los requerimientos minimos establecido por las normativas e indentificar posibles puntos de mejora. | J5: Anualmente, el Oficial de Cumplimiento de acuerdo a lo establecido en la Providencia 209 (Art 15), realiza una revisión de la estructura de PCLFT / PADM de la Corporación identificando lo siguiente: 1- Integrantes del sistema integral de PCLFT / PADM 2- Desginación del Oficial de Cumplimiento, 3- Aprobación de los responsables de Cumplimiento, 4- Unidad de Previsión y Control. La evidencia de este control es el archivo Excel que prepara el Oficial de cumplimiento donde se detallan los nombres de las personas que conforman el sistema integral de PCLFT/PADM. | M5: Oficial de Cumplimiento | N5: Manual | O5: Dectivo | P5: Anual
B6: PCLCFT. 02 Junta Directiva | C6: Actas de Juntas Directivas | D6: Artículo 16: La junta directiva del sujeto obligado tendrá las siguientes obligaciones: 1.Promover en todos los niveles de la organización, como componente del órgano de gobierno del sujeto obligado, la cultura de cumplimiento normativo del ordenamiento jurídico relacionado con la AR LC/FT/FPADM y Otros Ilícitos, procurando para ello que el personal se adhiera a las políticas, normas, procedimientos, mecanismos, instrumentos y sistemas de gestión de administración de riesgos adoptados. 2.Aprobar la designación de los siguientes integrantes del SIAR LC/FT/FPADM y otro Ilícitos: a.Oficial de Cumplimiento b.Miembros de la UAR LC/FT/FPADM y Otros Ilícitos c.Responsables de Cumplimiento para cada una de las áreas sensibles de riesgo de LC/FT/FPADM y otros Ilícitos. 3.Girar instrucciones para dar cumplimiento a los parámetros dictados por el oficial de cumplimiento para la implementación del SIAR LC/FT/FPADM y Otros Ilícitos, y asegurar que este cuente con suficiente autoridad y recursos (humanos, financieros y tecnológicos) para administrar un programa de cumplimiento en la AR LC/FT/FPADM y Otros Ilícitos, conforme al perfil de riesgo del sujeto obligado 4.Revisar y aprobar las políticas, estrategias, planes, informes, manuales, programas y planes de capacitación para las accionistas, miembros de la junta directiva, trabajadores o empleados y los relacionados con la actividad propia que desarrollan, así como los programas de AR LC/FT/FPADM y Otros Ilícitos, e implementación de tecnologías, presentados a su consideración por el oficial de cumplimiento. | E6: R02 | H6: PCLCFT. 02 | I6: Se realizó la revisión de la estructura de PCLCFTPADM con base a la Prov 209 y GAFILAT con el fin de validar que la misma cumpliera con los requerimientos minimos establecido por las normativas e indentificar posibles puntos de mejora. | J6: Anualmente, la Junta Directiva de acuerdo a lo establecido en la Providencia 209 (Art 16), realiza una revisión de sus siguientes obligaciones: 1.Instaurar una política sobre el cumplimiento de AR LC/FT/FPADM y Otros Ilícitos en todos los niveles de la organización. 2.Aprobar la designación y garantizar los recursos necesarios para la ejecución de las funciones de: a.El Oficial de Cumplimiento (OC) b.Los Miembros de la unidad c.Los responsables de Cumplimiento para cada una de las áreas 3.Revisar y aprobar: a.Las políticas y estrategias b.Los planes operativos de prevención y control (POA Y PASEC) c.Los informes presentados por el OC d.Los programas de adiestramiento e.El código de ética La evidencia de este control es un documento en Excel que prepara el Oficial de Cumplimiento donde se detallan los nombres de los funcionarios y las fechas de actualización de los informes. | M6: Oficial de Cumplimiento | N6: Manual | O6: Dectivo | P6: Anual
B7: PCLCFT. 03 RAS | C7: Reporte de Actividades Sospechosas | D7: Artículo 85: Los sujetos obligados deben reportar a través del formulario correspondiente, a la Unidad Nacional de Inteligencia Financiera (UNIF), la información de aquellas actividades que consideren sospechosas, vinculadas o no con los delitos de LC/FTFPADM y Otros Ilícitos, en un plazo que no debe exceder de treinta (30) días consecutivos siguientes a la fecha de realización de la operación. Si el sujeto obligado no ha tenido conocimiento de ninguna actividad sospechosa durante un lapso de un mes, deberá informar a la Superintendencia Nacional de Valores, dentro de los diez (10) días hábiles siguientes a la finalización de dicho termino. | E7: R03 | H7: PCLCFT. 03 | I7: Se realizó la revisión del RAS de PCLCFTPADM con base a la Prov 209 y GAFILAT con el fin de Verificar el cumplimiento en los tiempos establecidos de los envíos de reportes de actividades sospechosas. | J7: Mensualmente, el Oficial de Cumplimiento de acuerdo con lo establecido en la Providencia 209 (Art 85), debe reportar a través de un formulario la información de actividades que se consideren sospechosas vinculadas o no con los delitos de LC/FT/FPADM y Otros Ilícitos en un plazo que no debe exceder de treinta (30) días consecutivos siguientes a la fecha de realización de la operación. La evidencia de este control es el archivo Excel que prepara el Oficial de cumplimiento donde se detallan si ocurrieron actividades sospechosas, observaciones y fecha de la detección de las actividades. | M7: Oficial de Cumplimiento | N7: Manual | O7: Dectivo | P7: Anual
B8: PCLCFT. 04 Manual y Código de PCLCFT | C8: Manual de Políticas, Normas y Procedimientos de Prevensión y Control de LC/FT | D8: Artículo 41: Alcance Los mecanismos de gestión de riesgos adoptados por el sujeto obligado deben consolidarse en un manual de políticas, normas y procedimientos para la AR LC/FT/FPADM y Otros Ilícitos, considerando sus características propias, su naturaleza jurídica, así como los diferentes productos y servicios que ofrece a sus inversores o participantes. El manual de políticas, normas y procedimientos para la AR LC/FT/FPADM y Otros Ilícitos, debe ser aprobado por la junta directiva y ser remitido en formato digital a la Superintendencia Nacional de Valores, toda vez que sea elaborado por primera vez o tenga algunas actualizaciones de acuerdo al nivel de riesgo del sujeto obligado , sus cambios operativos, así como en el ordenamiento jurídico. En el expediente de cada empleado debe quedar constancia por escrito que ha tenido conocimiento del contenido del manual de políticas, normas y procedimientos de AR LC/FT/FPADM y Otros Ilícitos. Artículo 42: Contenido del Manual El manual de AR LC/FT/FPADM y Otros Ilícitos debe contener los aspectos mencionados en la providencia 209. Artículo 43: Actualización del Manual El sujeto obligado debe mantener actualizado el manual de AR LC/FT/FPADM y Otros Ilícitos, de acuerdo a las necesidades y a las nuevas disposiciones que se emitan, siendo aprobado por la junta directiva, debiendo estar disponible para que dichas actualizaciones sean revisadas durante los procedimientos de inspecciones que realice la Superintendencia Nacional de Valores o cuando le sea requerida mediante oficio. | E8: R04 | H8: PCLCFT. 04 | I8: Se realizó la revisión de PCLCFTPADM con base a la Prov 209 y GAFILAT con el fin de Verificar el cumplimiento Del Manual de Políticas, Normas y Procedimientos de Prevención y Control de LC/FT/PDADM | J8: Anualmente, el Oficial de Cumplimiento de acuerdo con lo establecido en la Providencia 209 (Art 41, 42 y 43), debe revisar el manual de políticas, normas y procedimientos para la AR LC/FT/FPADM y Otros Ilícitos ante posibles cambios y/o actualizaciones. La evidencia de este control es el documento en PDF titulado “Manual de AR LC/FT/FPADM y Otros Ilícitos” el cual debe contener los aspectos mencionados en la providencia 209 actualizado y luego ser revisado y aprobado por la Junta Directiva. | M8: Oficial de Cumplimiento | N8: Manual | O8: Dectivo | P8: Anual
B9: PCLCFT. 05 POA | C9: Plan Operatio Anual (POA) | D9: Artículo 29: Elaboración El Sujeto obligado debe diseñar y ejecutar un POA de AR LC/FT/FPADM y Otros Ilícitos, de conformidad con las disposiciones establecidas en sus manuales, a los fines de AR LC/FT/FPADM y Otros Ilícitos, y que estará en correlación con los cambios que experimenten los factores de riesgos asociados a los inversores, participantes, proveedores, productos o servicios, zonas geográficas, canales de distribución o comercialización y nuevas tecnologías, según los resultados evidenciados en el seguimiento de la autoevaluación del SIAR LC/FTFPADM y Otros Ilícitos, en la etapa de supervisión y monitoreo. Dicho plan debe ser elaborado y aprobado durante el último trimestre del año anterior a su ejecución y deberá ser consignado ante el Ente regulador, dentro de los quince (15) días hábiles del año de su ejecución. Artículo 30: Elementos que lo conforman El POA AR LC/FT/FPADM y Otros Ilícitos, deberá contener los siguientes elementos : -Actividades -Objetivos -Responsables -Unidad de medida -Metas -Insumos -Costos -Tiempo de ejecución -Otras Artículo 31: Informe de Ejecución El oficial de cumplimiento elaborara trimestralmente un informe sobre la ejecución del POA de AR LC/FT/FPADM y Otros Ilícitos, indicando el porcentaje de cumplimiento de cada aspecto de su contenido. Este documento debe formar parte de los informes trimestrales y anuales que el oficial de cumplimiento presentara a la junta directiva. El cual, deberá estar a disposición de cualquier auditoría de cumplimiento o inspección de la Superintendencia Nacional de Valores. | E9: R05 | H9: PCLCFT. 05 | I9: Se realizó la revisión de PCLCFTPADM con base a la Prov 209 y GAFILAT con el fin de Validar la elaboración del Plan Operativo Anual y los informes relacionados a éste y su conformidad con los lineamientos establecidos en las Normas sobre Prevención, Control y Fiscalización de los delitos de Legitimación de Capitales y el Financiamiento al Terrorismo, los cuales es obligación del Oficial de Cumplimiento presentarlos a la Junta Directiva de la Compañía y a la SUNAVAL si así se requiere. | J9: Anualemente, el Oficial de Cumplimiento de acuerdo con lo establecido en la Providencia 209 (Art 29, 30 y 31), debe elaborar un informe sobre la ejecución del POA de AR LC/FT/FPADM y Otros Ilícitos, indicando el porcentaje de cumplimiento de cada aspecto de su contenido. La evidencia de este control es el documento en PDF titulado “Plan Operativo Anual” el cual debe contener los aspectos mencionados en la providencia 209 actualizado y luego ser revisado y aprobado por la Junta Directiva. | M9: Oficial de Cumplimiento | N9: Manual | O9: Dectivo | P9: Trimestral
B10: PCLCFT. 06 Revisión de Expedientes | C10: Revisión expedientes: Empleados | D10: Artículo 11: El sujeto obligado debe evaluar y ponderar los riesgos inherentes a la LC/FT/FPADM y Otros Ilícitos, clasificarlos según su perfil de riesgo entre altos, medios y bajos, o una clasificación más extendida, a los fines de desarrollar una adecuada, eficiente y eficaz administración de los riesgos identificados, entre sus empleados, inversores, participantes, actores del mercado, proveedores, productos o servicios, zonas geográficas, canales de distribución o comercialización y nuevas tecnologías vinculadas a estos. Artículo 36: Cada inducción, formación o capacitación sobre la AR LC/FT/FPADM debe constar en un documento elaborado por el sujeto obligado, donde se especifique su denominación y contenido, suscrito por el oficial de cumplimiento y los participantes, el cual debe reposar en sus expedientes y mantenerse a la disposición de la SUNAVAL. Artículo 41: Los mecanismos de gestión de riesgos adoptados por el sujeto obligado deben consolidarse en un manual de políticas, normas y procedimientos para la AR LC/FT/FPADM y Otros Ilícitos, considerando sus características propias, su naturaleza jurídica, así como los diferentes productos y servicios que ofrece a sus inversores o participantes. El manual de políticas, normas y procedimientos para la AR LC/FT/FPADM y Otros Ilícitos, debe ser aprobado por la junta directiva y ser remitido en formato digital a la Superintendencia Nacional de Valores, toda vez que sea elaborado por primera vez o tenga algunas actualizaciones de acuerdo al nivel de riesgo del sujeto obligado , sus cambios operativos, así como en el ordenamiento jurídico. En el expediente de cada empleado debe quedar constancia por escrito que ha tenido conocimiento del contenido del manual de políticas, normas y procedimientos de AR LC/FT/FPADM y Otros Ilícitos. Artículo 63.- La gerencia de gestión y talento humano del sujeto obligado apoyado por el oficial de cumplimiento, debe formular e implementar una política de “Conozca su Empleado” que establezca un procedimiento de selección del personal (Nuevos ingresos) acorde con sus niveles de riesgo, verificando lo datos e informaciones por ellos aportados, así como las referencias de trabajos anteriores. Artículo 64.- El sujeto obligado debe formar un expediente por cada empleado, que reposará en el área encargada de gestión y talento humano y debe estar a disposición de la SUNAVAL cuando este sea requerido por los funcionarios durante el procedimiento de inspección, así como de los organismos de control correspondientes, el expediente debe contener lo establecido en los manuales, instructivos, formatos y disposiciones normativas dictadas al efecto. Artículo 66.- (PEP) EI sujeto obligado debe tomar las medidas necesarias para mitigar el riesgo de participar deliberada o involuntariamente, en el encubrimiento de ejecución de operaciones derivadas de hechos ilícitos, por parte de figuras politices nacionales o extranjeras de alto nivel y su círculo de colaboradores. Artículo 66: Los sujetos obligados deben tomar las medidas reforzadas de debida diligencia cuando mantengan relaciones comerciales, de negocios u operaciones con clientes que son considerados bajo el perfil de una persona expuesta políticamente, nacionales o extranjeras de alto nivel y su círculo de colaboradores. Debido a que los riesgos planteados por las personas expuestas políticamente varían la identificación, monitoreo y el diseño de sistemas de gestión de riesgos para estos inversores, participantes o proveedores, y las transacciones efectuadas en sus cuentas deben estar basados según perfil de riesgo, de conformidad con lo establecido en los manuales, instructivos, formatos y disposiciones normativas dictadas al efecto. | E10: R06 | H10: PCLCFT. 06 | J10: Bianualmente, el Oficial de Cumplimiento de acuerdo con lo establecido en la Providencia 209 (Art 11, 36, 41, 63, 64, 66), debe mantener al día los expedientes de los empleados, incluyendo dentro de ellos: -Ficha del empleado actualizada -Documentos consignados por el empleado -Clasificación de su perfil de riesgo -Confirmación de asistencia a inducciones, formaciones o capacitaciones. -Constancia por escrito sobre el conocimiento del contenido del manual de políticas, normas y procedimientos de AR LC/FT/FPADM y Otros Ilícitos. -Verificación de antecedentes en las listas de verificación (ONU,OFAC). La evidencia de este control es un archivo Excel que prepara el Oficial de cumplimiento donde se tiene una lista de todos los empleados y los requerimientos de su expediente con su fecha de actualización del expediente. | M10: Oficial de Cumplimiento | N10: Manual | O10: Dectivo | P10: Anual
B11: PCLCFT. 06 Revisión de Expedientes | C11: Revisión expedientes: Inversores | D11: Artículo 10: El sujeto obligado debe efectuar la segmentación mediante la consolidación de los factores de riesgo y demás variables, a través de la creación de los perfiles de riesgos, fundamentándose en el reconocimiento de diferencias significativas, de conformidad con el conocimiento de éstos, la naturaleza de sus operaciones, disponibilidad de datos y tomando en cuenta, como mínimo, las siguientes variables para cada segmento: a) Tipo de Emisor, Inversor, Participante o Proveedor b)Actividades económicas a las que se dedican c)Origen de los recursos Artículo 11: El sujeto obligado debe evaluar y ponderar los riesgos inherentes a la LC/FT/FPADM y Otros Ilícitos, clasificarlos según su perfil de riesgo entre altos, medios y bajos, o una clasificación más extendida, a los fines de desarrollar una adecuada, eficiente y eficaz administración de los riesgos identificados, entre sus empleados, inversores, participantes, actores del mercado, proveedores, productos o servicios, zonas geográficas, canales de distribución o comercialización y nuevas tecnologías vinculadas a estos. Artículo 12: El sujeto obligado debe dar un nivel de riesgo a cada factor (Inversores, Emisores, Participantes o Proveedores), cuantificar la incidencia del riesgo (impacto) y considerar como de alto riesgo en su SIAR LC/FT/FPADM y Otros Iliciticos. Artículo 45 y 46: Los sujetos obligados, bajo un enfoque basado de riesgo, debe llevar un registro individual por cada uno de sus inversores, a objeto de obtener y mantener actualizada la información de las operaciones independientemente del monto que este realice con el sujeto obligado, mientras dure su vinculación comercial, a fin de comprobar fehacientemente su identificación, incluyendo su beneficiario final y las actividades económicas a las que se dedican, adaptando parámetros de segmentación, para definir su perfil financiero, identificando las operaciones inusuales o sospechosas, rangos en los cuales se desarrollen las operaciones que realizan los inversoras y las características de estas en el mercada tradicional de valores. Articulo 48: El sujeto obligado de acuerdo a su perfil y a los riesgos potenciales presentados por los inversores, debe emplear diferentes métodos para verificar la identidad y los datos aportados por estos. A mayor nivel de riesgo se emplearán métodos mas intensificados, pormenorizados o estrictos y seguir los procedimientos establecidos en los manuales, instructivos, formatos y disposiciones normativas distadas al efecto. Artículo 49: Los documentos obtenidos del inversor y sus actividades, conformaran un expediente, el cual permanecerá en la oficina o sucursal del sujeto obligado, donde fue abierta la cuenta de corretaje bursátil, debe contener lo establecido en los manuales, instructivas, formatos y lo dispuesto en el presente capitulo, incluyendo: 1.Documentos consignados por el inversor, según lo establecido en los requisitos para el registro 2.Ficha de identificación del inversor 3.Contrato de apertura de cuenta de corretaje bursátil o contrato de servicios 4. Cualquier otro documento relacionado con el inversor y sus actividades. Articulo 66: Los sujetos obligados deben tomar las medidas reforzadas de debida diligencia cuando mantengan relaciones comerciales, de negocios u operaciones con clientes que son considerados bajo el perfil de una persona expuesta políticamente, nacionales o extranjeras de alto nivel y su circulo de colaboradores. Debido a que los riesgos planteados por las personas expuestas políticamente varían la identificación, monitoreo y el diseño de sistemas de gestión de riesgos para estos inversores, participantes o proveedores, y las transacciones efectuadas en sus cuentas deben estar basados según perfil de riesgo, de conformidad con lo establecido en los manuales, instructivos, formatos y disposiciones normativas dictadas al efecto. Artículo 68: Las sociedades cuyos valores sean objeto de oferta pública deberán suministrar dentro de siete (7) días continuos, siguientes a la celebración de la respectiva asamblea de accionistas, un informe sobre los métodos y procedimientos aplicados en su organización, para prevenir la utilización de los mismos como medio para legitimar capitales, de conformidad con la ley y normas vigentes que regulen la materia. | E11: R07 | H11: PCLCFT. 07 | J11: Bianualmente, el Oficial de Cumplimiento de acuerdo con lo establecido en la Providencia 209 (Art 10, 11, 12, 45, 46, 48, 49, 66, 68), debe mantener al día los expedientes de los inversores, incluyendo dentro de ellos: -Documentos consignados por el inversor -Ficha de identificación del inversor -Contrato de apertura de cuenta de corretaje bursátil o contrato de servicios -Cualquier otro documento relacionado con el inversor y sus actividades. -Clasificación de su perfil de riesgo -Verificación de antecedentes (incluyendo PEP) en las listas de verificación (ONU,OFAC). La evidencia de este control es un archivo Excel que prepara el Oficial de cumplimiento donde se tiene una lista de todos los inversores y los requerimientos de su expediente con su fecha de actualización del expediente.
B12: PCLCFT. 06 Revisión de Expedientes | C12: Revisión expedientes: Participantes | D12: Artículo 10: El sujeto obligado debe efectuar la segmentación mediante la consolidación de los factores de riesgo y demás variables, a través de la creación de los perfiles de riesgos, fundamentándose en el reconocimiento de diferencias significativas, de conformidad con el conocimiento de éstos, la naturaleza de sus operaciones, disponibilidad de datos y tomando en cuenta, como mínimo, las siguientes variables para cada segmento: a) Tipo de Emisor, Inversor, Participante o Proveedor b)Actividades económicas a las que se dedican c)Origen de los recursos Artículo 11: El sujeto obligado debe evaluar y ponderar los riesgos inherentes a la LC/FT/FPADM y Otros Ilícitos, clasificarlos según su perfil de riesgo entre altos, medios y bajos, o una clasificación mas extendida, a los fines de desarrollar una adecuada, eficiente y eficaz administración de los riesgos identificados, entre sus empleados, inversores, participantes, actores del mercado, proveedores, productos o servicios, zonas geográficas, canales de distribución o comercialización y nuevas tecnologías vinculadas a estos. Artículo 12: El sujeto obligado debe dar un nivel de riesgo a cada factor (Inversores, Emisores, Participantes o Proveedores), cuantificar la incidencia del riesgo (impacto) y considerar como de alto riesgo en su SIAR LC/FT/FPADM y Otros Iliciticos. Artículo 56: Una vez completado el registro, el participante declara y acepta: 4.Proveer cualquier otra información que le sea requerida, para verificar su identidad o la traza de alguna operación realizada en la plataforma tecnológica de mercados descentralizados de valores, en virtud de AR LC/FT/FPADM y Otros Ilícitos. 5.Que los datos suministrados están completos, son ciertos y verificables. 12. que dicha información sea almacenada durante un periodo mínimo de cinco (5) años desde su registro y que pueda ser compartida con las autoridades competentes, en el caso de que exista un requerimiento judicial expreso en ese sentido. | E12: R08 | H12: PCLCFT. 08 | J12: Bianualmente, el Oficial de Cumplimiento de acuerdo con lo establecido en la Providencia 209 (Art 10, 11, 12, 56.4, 56.5, 56.12), debe mantener al día los expedientes de los participantes, incluyendo dentro de ellos: -Documentos consignados por el participante -Ficha de identificación del participante -Clasificación de su perfil de riesgo -Verificación de antecedentes en las listas de verificación (ONU,OFAC). La evidencia de este control es un archivo Excel que prepara el Oficial de cumplimiento donde se tiene una lista de todos los participantes y los requerimientos de su expediente con su fecha de actualización del expediente.
B13: PCLCFT. 06 Revisión de Expedientes | C13: Revisión expedientes: Proveedores | D13: Artículo 10: El sujeto obligado debe efectuar la segmentación mediante la consolidación de los factores de riesgo y demás variables, a través de la creación de los perfiles de riesgos, fundamentándose en el reconocimiento de diferencias significativas, de conformidad con el conocimiento de éstos, la naturaleza de sus operaciones, disponibilidad de datos y tomando en cuenta, como mínimo, las siguientes variables para cada segmento: a) Tipo de Emisor, Inversor, Participante o Proveedor b)Actividades económicas a las que se dedican c)Origen de los recursos Artículo 11: El sujeto obligado debe evaluar y ponderar los riesgos inherentes a la LC/FT/FPADM y Otros Ilícitos, clasificarlos según su perfil de riesgo entre altos, medios y bajos, o una clasificación más extendida, a los fines de desarrollar una adecuada, eficiente y eficaz administración de los riesgos identificados, entre sus empleados, inversores, participantes, actores del mercado, proveedores, productos o servicios, zonas geográficas, canales de distribución o comercialización y nuevas tecnologías vinculadas a estos. Artículo 12: El sujeto obligado debe dar un nivel de riesgo a cada factor (Inversores, Emisores, Participantes o Proveedores), cuantificar la incidencia del riesgo (impacto) y considerar como de alto riesgo en su SIAR LC/FT/FPADM y Otros Iliciticos. Articulo 60: Los Sujetos obligados deben mantener un registro individual de cada uno de los proveedores de servicios, con los que establezca una relación financiera, comercial o de negocios; aplicando un enfoque basado en riesgos, para la recabar la información necesaria de su identificación, a los fines de realizar la verificación correspondiente, al momento de iniciar el vínculo financiero, comercial o de negocios. Artículo 61: L identificación del proveedor de servicios se realizará utilizando las mismas reglas utilizadas en la política conozca a su inversor, en cuento le sean aplicables. Artículo 62: La verificación de la información podrá efectuarse a través de los órganos y entes de la Administración Publica Nacional y otras fuentes abiertas o cerradas, que permita la comprobación de los datos de sus proveedores de servicios, debiendo mantener su expediente actualizado y revisado anualmente. Artículo 66: Los sujetos obligados deben tomar las medidas reforzadas de debida diligencia cuando mantengan relaciones comerciales, de negocios u operaciones con clientes que son considerados bajo el perfil de una persona expuesta políticamente, nacionales o extranjeras de alto nivel y su círculo de colaboradores. Debido a que los riesgos planteados por las personas expuestas políticamente varían la identificación, monitoreo y el diseño de sistemas de gestión de riesgos para estos inversores, participantes o proveedores, y las transacciones efectuadas en sus cuentas deben estar basados según perfil de riesgo, de conformidad con lo establecido en los manuales, instructivos, formatos y disposiciones normativas dictadas al efecto. Artículo 68: Las sociedades cuyos valores sean objeto de oferta pública deberán suministrar dentro de siete (7) días continuos, siguientes a la celebración de la respectiva asamblea de accionistas, un informe sobre los métodos y procedimientos aplicados en su organización, para prevenir la utilización de los mismos como medio para legitimar capitales, de conformidad con la ley y normas vigentes que regulen la materia. | E13: R09 | H13: PCLCFT. 09 | J13: Bianualmente, el Oficial de Cumplimiento de acuerdo con lo establecido en la Providencia 209 (Art 10, 11, 12, 66, 68), debe mantener al día los expedientes de los proveedores, incluyendo dentro de ellos: -Ficha del proveedor actualizada -Documentos consignados por el proveedor -Clasificación de su perfil de riesgo -Verificación de antecedentes en las listas de verificación (ONU,OFAC). La evidencia de este control es un archivo Excel que prepara el Oficial de cumplimiento donde se tiene una lista de todos los proveedores y los requerimientos de su expediente con su fecha de actualización del expediente.
B14: PCLCFT. 06 Revisión de Expedientes | C14: Revisión expedientes: Accionista | D14: Artículo 10: El sujeto obligado debe efectuar la segmentación mediante la consolidación de los factores de riesgo y demás variables, a través de la creación de los perfiles de riesgos, fundamentándose en el reconocimiento de diferencias significativas, de conformidad con el conocimiento de éstos, la naturaleza de sus operaciones, disponibilidad de datos y tomando en cuenta, como mínimo, las siguientes variables para cada segmento: a) Tipo de Emisor, Inversor, Participante o Proveedor b)Actividades económicas a las que se dedican c)Origen de los recursos Artículo 11: El sujeto obligado debe evaluar y ponderar los riesgos inherentes a la LC/FT/FPADM y Otros Ilícitos, clasificarlos según su perfil de riesgo entre altos, medios y bajos, o una clasificación más extendida, a los fines de desarrollar una adecuada, eficiente y eficaz administración de los riesgos identificados, entre sus empleados, inversores, participantes, actores del mercado, proveedores, productos o servicios, zonas geográficas, canales de distribución o comercialización y nuevas tecnologías vinculadas a estos. Artículo 41: Los mecanismos de gestión de riesgos adoptados por el sujeto obligado deben consolidarse en un manual de políticas, normas y procedimientos para la AR LC/FT/FPADM y Otros Ilícitos, considerando sus características propias, su naturaleza jurídica, así como los diferentes productos y servicios que ofrece a sus inversores o participantes. El manual de políticas, normas y procedimientos para la AR LC/FT/FPADM y Otros Ilícitos, debe ser aprobado por la junta directiva y ser remitido en formato digital a la Superintendencia Nacional de Valores, toda vez que sea elaborado por primera vez o tenga algunas actualizaciones de acuerdo al nivel de riesgo del sujeto obligado , sus cambios operativos, así como en el ordenamiento jurídico. En el expediente de cada empleado debe quedar constancia por escrito que ha tenido conocimiento del contenido del manual de políticas, normas y procedimientos de AR LC/FT/FPADM y Otros Ilícitos. Artículo 58: El objetivo de esta política es mantener actualizada toda la información de los accionistas, a fin de aplicar la debida diligencia en función a los riesgos identificados y que le permita al sujeto obligado a tomas las medidas idóneas para AR LC/FT/FPADM, cuando se inicie la relación accionaria o cuando existen cambio en la información del accionista. Artículo 59: El o los accionistas, declaran y aceptan, que: 5.El sujeto obligado mantenga sus datos en forma física o digital durante un periodo mínimo de cinco (5) años desde su ingreso y que pueda ser compartida con las autoridades competentes, en el caso de que exista un requerimiento judicial expreso en ese sentido. Artículo 66: Los sujetos obligados deben tomar las medidas reforzadas de debida diligencia cuando mantengan relaciones comerciales, de negocios u operaciones con clientes que son considerados bajo el perfil de una persona expuesta políticamente, nacionales o extranjeras de alto nivel y su círculo de colaboradores. Debido a que los riesgos planteados por las personas expuestas políticamente varían la identificación, monitoreo y el diseño de sistemas de gestión de riesgos para estos inversores, participantes o proveedores, y las transacciones efectuadas en sus cuentas deben estar basados según perfil de riesgo, de conformidad con lo establecido en los manuales, instructivos, formatos y disposiciones normativas dictadas al efecto. Artículo 68: Las sociedades cuyos valores sean objeto de oferta pública deberán suministrar dentro de siete (7) días continuos, siguientes a la celebración de la respectiva asamblea de accionistas, un informe sobre los métodos y procedimientos aplicados en su organización, para prevenir la utilización de los mismos como medio para legitimar capitales, de conformidad con la ley y normas vigentes que regulen la materia. | E14: R10 | H14: PCLCFT. 10 | J14: Bianualmente, el Oficial de Cumplimiento de acuerdo con lo establecido en la Providencia 209 (Art 10, 11, 41, 58, 59.5, 66, 68), debe mantener al día los expedientes de los accionistas, incluyendo dentro de ellos: -Ficha del accionista actualizada -Documentos consignados por el accionista -Clasificación de su perfil de riesgo -Verificación de antecedentes en las listas de verificación (ONU,OFAC). La evidencia de este control es un archivo Excel que prepara el Oficial de cumplimiento donde se tiene una lista de todos los acccionistas y los requerimientos de su expediente con su fecha de actualización del expediente.
B15: PCLCFT. 06 Revisión de Expedientes | C15: Revisión expedientes: Clientes | E15: R11 | H15: PCLCFT. 11 | J15: La evidencia de este control es un archivo Excel que prepara el Oficial de cumplimiento donde se tiene una lista de todos los clientes y los requerimientos de su expediente con su fecha de actualización del expediente.
B16: PCLCFT.12 Programa Anual de Adiestramiento | C16: Plan Anual de Adiestramiento | D16: Artículo 32: El sujeto obligado debe diseñar, financiar e implementar un programa anual de formación y capacitación para la AR LC/FT/FPADM y Otros Ilícitos, de conformidad con las disposiciones establecidas por el Ente regulador, ajustando el perfil operacional a los riesgos identificados y relacionados con la LC/FT/FPADM y Otros Ilícitos. Este programa estará dirigido a todo el personal ejecutivo, directivo, empleados y trabajadores y representantes autorizados según las responsabilidades y actividades que desempeñe cada grupo. El programa anual debe ser presentado dentro de los primeros quince (15) días continuos del ejercicio fiscal en curso por el oficial de cumplimiento ante la junta directiva del sujeto obligado para su aprobación, el cual debe estar a disposición del Ente regulador. Artículo 33: El programa anual de formación y capacitación debe contener los objetivos específicos, las estrategias de enseñanza, los mecanismos e instrumentos y métodos de evaluación a ser aplicados. Para su diseño, el sujeto obligado debe considerar las funciones específicas de cada área a la cual va dirigido. Articulo 35: El sujeto obligado debe documentar el cumplimiento de sus programas de formación y capacitación, debiendo además llevar los registros de las actividades que incluyan pruebas documentales, fechas de las sesiones de formación y capacitación, así como la asistencia a las mismas. Dicha documentación, debe estar a disposición de la Superintendencia Nacional de Valores, para su revisión y mantenerse por un periodo mínimo de cinco (5) años, contados a partir de la realización de la formación y capacitación, la documentación debe adecuarse de conformidad con las disposiciones establecidas. | E16: R12 | H16: PCLCFT. 12 | I16: Se realizó la revisión de PCLCFTPADM con base a la Prov 209 y GAFILAT con el fin de Validar la elaboración del Programa Anual de Adiestramiento, verificar que los adiestramientos de hayan realizado efectivamente y su conformidad con los lineamientos establecidos en las Normas sobre Prevención, Control y Fiscalización de los delitos de Legitimación de Capitales y el Financiamiento al Terrorismo y FPDADM. | J16: Anualmente, el Oficial de Cumplimiento de acuerdo con lo establecido en la Providencia 209 (Art 32, 33 y 35), debe desarrollar un programa de formación y capacitación para la AR LC/FT/FPADM y Otros Ilícitos. La evidencia de este control es un archivo en Excel que prepara el Oficial de cumplimiento donde se documentan los registros de las actividades que incluyan pruebas documentales, fechas de las sesiones de formación y capacitación, así como la asistencia a las mismas. | M16: Oficial de Cumplimiento | N16: Manual | O16: Dectivo | P16: Anual
B17: PCLCFT.08 Comunicaciones con la SUNAVAL | C17: Comunicaciones a la SUNAVAL | D17: Artículo 17: El presidente o quien haga sus veces en la estructura organizativa del sujeto obligado, debe cumplir las siguientes obligaciones: 6.Informar a la SUNAVAL sobre la postulación, renuncia y ausencia del oficial de cumplimiento, dentro de un lapso de (15) días hábiles siguientes a la fecha de su nombramiento en acta de junta directiva, acompañado de la declaración jurada en la que manifesté estar en el ejercicio de las funciones a dedicación exclusiva , resumen curricular con los respectivos soportes y la certificación del acta de la junta directiva donde consté su designación. 7.Nombrar al director o gerente de la UAR, para cumplir las funciones del oficial de cumplimiento, en el caso de las ausencias debidamente justificadas. Ahora bien, en el caso de renuncia o despido de este, se deberá designar a un nuevo oficial de cumplimiento m en un lapse de treinta (30) días hábiles. Dicho reemplazo deberá ser notificado a la SUNAVAL dentro de los tres (03) días hábiles siguientes a efectuarse el referido movimiento. 8.En caso de no existir la conformación de la UAR LC/FT/FPADM, el presidente deberá designar a un responsable de cumplimiento de las áreas sensibles de riesgo, para que ejerza temporalmente las funciones del cumplimiento por un tiempo máximo de tres (03) meses, cumplido este lapso, el sujeto obligado deberá; nombrar en quince (15) días continuos siguientes un nuevo oficial de cumplimiento. 9.Informar a la SUNAVAL, sobre la designación de los integrantes de la UAR LC/FT/FPADM y Otros Ilícitos, dentro de un lapso de (15) días hábiles siguientes a la fecha de su nombramiento, y remitir a esta la declaración jurada en la que manifiesten estar en el ejercicio de las funciones a dedicación exclusiva, resumen curricular con los respectivos soportes y la certificación del acta de la junta directiva donde consten sus designaciones. Artículo 20: El oficial de cumplimiento tendrá las siguientes obligaciones 17. Informar a la SUNAVAL los reportes de transacciones sospechosas e información relevante relacionada con la AR LC/FT/FPADM y Otros Ilícitos, así como las respuestas a las solicitudes de información en esta materia, llevadas a cabo por las autoridades competentes, todo ello dentro de los plazos establecidos en la normativa legal vigente. 19. Mantener relaciones institucionales con la SUNAVAL Artículo 24: El gerente de la UAR LC/FT/FPADM y Otros Ilícitos, tendrá las siguientes obligaciones: 10. Remitir a la SUNAVAL, la identificación, cargo y teléfono laboral de las personas que conforman la UAR LC/FT/FPADM y Otros Ilícitos, manteniendo actualizada esta información, dicha remisión deberá realizarse en un plazo de quince (15) días hábiles, contados a partir de la fecha en que se designe al personal o se efectúen los nuevos nombramientos. 11. Remitir a la SUNAVAL, el organigrama funcional de la UAR LC/FT/FPADM y Otros Ilícitos, una vez conformada esta Artículo 38: El código de ética o código de conducta debe ser aprobado por la junta directiva del sujeto obligado y estar disponible para su revisión por parte de los funcionarios de la SUNAVAL, durante las inspecciones. Artículo 41: El manual de políticas, normas y procedimientos de AR /LC/FT/FPADM y otros ilícitos, debe ser aprobado por la junta directiva y ser remitido en formato digital a la SUNAVAL, toda vez que sea elaborado por primera vez o tenga algunas actualizaciones de acuerdo al nivel de riesgo del sujeto obligado, sus cambios operativos, así como en el ordenamiento jurídico. Artículo 68: Las sociedades cuyos valores sean objeto de oferta pública deberán suministrar dentro de siete (7) días continuos, siguientes a la celebración de la respectiva asamblea de accionistas, un informe sobre los métodos y procedimientos aplicados en su organización, para prevenir la utilización de los mismos como medio para legitimar capitales, de conformidad con la ley y normas vigentes que regulen la materia. Artículo 76: Presentación del informe anual: El informe anual preparado por el tercero independiente calificado de cumplimiento debe hacerse del conocimiento de la junta directiva del sujeto obligado, con copia al oficial de cumplimiento y ser remido dentro de los noventa (90) días continuos siguientes al cierre del ejercido fiscal de cada sujeto obligado a la Superintendencia Nacional de Valores, quien formulará observaciones correspondientes. Asimismo, el sujeto obligado debe mantener disponible, al momento de la inspección por parte del ente regulador, el informe anual a los unes de revisar su implementación. Artículo 82: Cuando la SUNAVAL o los organismos competentes soliciten información al oficial de cumplimiento del sujeto obligado sobre las actividades vinculadas a los delitos de LC/FTFPADM y Otros Ilícitos, que estén siento objeto de investigación, dentro de las limitaciones establecidas en las leyes y las que se derivan de sus actividades dentro del mercado de valores, deben establecer mecanismos coordinados que permitan la investigación, seguimiento e intercambio de información sobre las actividades sospechosas, que estén siendo objeto de investigación por parte d ellos mencionados organismos. Artículo 84: La información solicitada por los órganos de investigación del Estado, con competencia en la materia o por la SUNAVAL, se remitirá incluyendo los detalles solicitados sobre las operaciones realizadas, anexando una copia de los documentos necesarios que permitan la verificación de la información suministrada, siendo el plazo para cumplir con esta obligación el indicado en el requerimiento para cada caso. El procedimiento que será utilizado para las solicitudes de información emanadas de la SUNAVAL, será de conformidad con lo establecido en las disposiciones establecidas y dictadas al efecto. Artículo 85: Los sujetos obligados deben reportar a través del formulario correspondiente, a la Unidad Nacional de Inteligencia Financiera (UNIF), la información de aquellas actividades que consideren sospechosas, vinculadas o no con los delitos de LC/FTFPADM y Otros Ilícitos, en un plazo que no debe exceder de treinta (30) días consecutivos siguientes a la fecha de realización de la operación. Si el sujeto obligado no ha tenido conocimiento de ninguna actividad sospechosa durante un lapso de un mes, deberá informar a la Superintendencia Nacional de Valores, dentro de los diez (10) días hábiles siguientes a la finalización de dicho termino. | E17: R13 | H17: PCLCFT. 13 | I17: Se realizó la revisión de PCLCFTPADM con base a la Prov 209 con el fin de Validar el cumplimiento con la remisión d einformación y documentos epsecíficos que indica la normativa en el tiempo y adecuadamente según sea el caso a la SUNAVAL. | J17: Anualmente, el Oficial de Cumplimiento de acuerdo con lo establecido en la Providencia 209 (Art 17, 20, 24, 38, 41, 68, 76, 82, 84), debe de validar el cumplimiento con la remisión de información y documentos específicos que demanda la SUNAVAL, siendo estos: -Documentación sobre la postulación, renuncia y ausencia del oficial de cumplimiento, -Responsable de cumplimiento de las áreas sensibles de riesgo (en caso de no existir la conformación de la UAR LC/FT/FPADM -Designación de los integrantes de la UAR LC/FT/FPADM y Otros Ilícitos -Información (identificación, cargo y teléfono laboral) sobre las personas que conforman la UAR LC/FT/FPADM y Otros Ilícitos. -Establecimiento del organigrama funcional de la UAR LC/FT/FPADM y Otros Ilícitos -Informe anual sobre la AR /LC/FT/FPADM y Otros Ilícitos -Código de ética o código de conducta -Manual de políticas, normas y procedimientos de AR /LC/FT/FPADM y otros ilícitos -Informe sobre los métodos y procedimientos aplicados para la prevención de la utilización de cualquier valor o derecho de contenido financiero objeto de oferta pública como medio para legitimar capitales, de conformidad con la ley y normas vigentes que regulen la materia. La evidencia de este control es un archivo en Excel que prepara el Oficial de cumplimiento donde se lleva un control y supervisión de los expedientes mantenidos, para cumplir con los parámetros de posibles revisiones de la SUNAVAL. | M17: Oficial de Cumplimiento | N17: Manual | O17: Dectivo | P17: Anual
B18: PCLCFT.09 Manual de Gobierno Corporativo | C18: Manual de Gobierno Corporativo | D18: Artículo 40: Gobierno corporativo La junta directiva del sujeto obligado debe elaborar, aprobar y firmar de forma individual el manual de buen gobierno corporativo bajo las directrices que la SUNAVAL dicte al respecto, en señal que lo conoce y acepta sus directrices, y se obliga a la supervisión de su implementación y ejecución. | E18: R14 | H18: PCLCFT. 14 | J18: Anualmente, el Oficial de Cumplimiento de acuerdo con lo establecido en la Providencia 209 (Art 40), debe revisar el Manual de Gobierno Corporativo ante posibles cambios y/o actualizaciones. La evidencia de este control es el documento en PDF titulado “Manual de Gobierno Corporativo” el cual debe contener los aspectos mencionados en la providencia 209 actualizado y luego ser revisado y aprobado por la Junta Directiva.

Sheet RACMDEF
G2: Criterios de valoración de riesgos
G3: Escala | H3: Ponderación | I3: Probabilidad de ocurrencia | O3: Leyenda de controles
G4: 5 | H4: Muy Alto | I4: Muy probable | O4: Control sugerido
G5: 4 | H5: Alto | I5: Moderado | O5: Control con oportunidad de mejora
B6: Providencia 209 - Administración de Riesgos de LC/FT/FPADM y otros ilicitos | G6: 3 | H6: Medio | I6: Probable | O6: Control actual (según entrevista con el área)
B7: Matriz de Riesgos y Controles | G7: 2 | H7: Bajo | I7: Ocasional | O7: =N10+1 -> 1
G8: 1 | H8: Muy Bajo | I8: Improbable
B10: 1 | C10: =B10+1 -> 2 | D10: =C10+1 -> 3 | E10: =D10+1 -> 4 | F10: =E10+1 -> 5 | G10: =F10+1 -> 6 | H10: =G10+1 -> 7 | I10: =H10+1 -> 8 | J10: =I10+1 -> 9 | ... L10: =K10+1 -> 11 | M10: Descripción del control | P10: Responsabilidad del control | R10: Características del control | V10: =#REF!+1 -> #REF!
A11: 1 | B11: Título | C11: Art. Prov. 209 | E11: ID del Riesgo | F11: Segmentación | G11: Ponderación/ Impacto (A,M,B) | H11: Valor Ponderación/ Impacto | I11: Probabilidad de ocurrencia (M, P, M, O, I) | J11: Valor Probabilidad de ocurrencia | K11: Tipo de Riesgo | L11: Descripción del Riesgo | M11: ID Control | N11: Vigencia del control (esta columan es temporal) | O11: Propuesta de Redacción de Control | P11: Área o Dpto responsable | Q11: Responsable | R11: Tipo | S11: Naturaleza | T11: Frecuencia | U11: Control clave (s/n) | V11: Comentarios
A12: =A11+1 -> 2 | B12: PCLCFT. 01 Administración de riesgo | C12: Capítulo II. Sistema Integrado de Administración de Riesgos relacionados con delitos de Legitimación de Capitales, Financiamiento al Terrorismo, Financiamiento de la Proliferación de Armas de Destrucción Masiva (LC/FT/FPADM) y otros Ilícitos. | D12: Artículo 10: El sujeto obligado debe efectuar la segmentación mediante la consolidación de los factores de riesgo y demás variables, a través de la creación de los perfiles de riesgos, fundamentándose en el reconocimiento de diferencias significativas, de conformidad con el conocimiento de éstos, la naturaleza de sus operaciones, disponibilidad de datos y tomando en cuenta, como mínimo, las siguientes variables para cada segmento: a) Tipo de Emisor, Inversor, Participante o Proveedor b)Actividades económicas a las que se dedican c)Origen de los recursos Artículo 11: El sujeto obligado debe evaluar y ponderar los riesgos inherentes a la LC/FT/FPADM y Otros Ilícitos, clasificarlos según su perfil de riesgo entre altos, medios y bajos, o una clasificación más extendida, a los fines de desarrollar una adecuada, eficiente y eficaz administración de los riesgos identificados, entre sus empleados, inversores, participantes, actores del mercado, proveedores, productos o servicios, zonas geográficas, canales de distribución o comercialización y nuevas tecnologías vinculadas a estos. Artículo 12: El sujeto obligado debe dar un nivel de riesgo a cada factor (Inversores, Emisores, Participantes o Proveedores), cuantificar la incidencia del riesgo (impacto) y considerar como de alto riesgo en su SIAR LC/FT/FPADM y Otros Iliciticos | E12: R01 | F12: 1a.Tipo de EIPP | G12: Alto | H12: 5 | I12: Moderado | J12: 4 | K12: Cumplimiento | L12: Errores en la asignación de los factores de riesgos a los inversores, emisores, participantes o proveedores. | M12: PCLCFT01 | N12: Sugerido | O12: Cada vez que ingrese un nuevo inversor, accionista, participante, empleado, cliente, proveedor o cualquier persona natural o jurídica, el Oficial de Cumplimiento de acuerdo con lo establecido en la Providencia 209 (Art 10, 11, 12, 60, 61, 62 66, 68), deben velar por la completitud de los siguientes formularios (según aplique): -Ficha del proveedor actualizada -Documentos consignados -Clasificación de su perfil de riesgo -Verificación de antecedentes en las listas de verificación (ONU,OFAC). | P12: UAR | Q12: Oficial de Cumplimiento | R12: Preventivo | S12: Manual | T12: Cada vez que ocurra | U12: Si | V12: Ejemplo de como llenar la información del control
A13: =A12+1 -> 3 | B13: PCLCFT. 01 Administración de riesgo | C13: Capítulo II. Sistema Integrado de Administración de Riesgos relacionados con delitos de Legitimación de Capitales, Financiamiento al Terrorismo, Financiamiento de la Proliferación de Armas de Destrucción Masiva (LC/FT/FPADM) y otros Ilícitos. | D13: Artículo 12 #4: El sujeto obligado debe dar un nivel de riesgo a cada factor…: #4 Canales de distribución y comercialización. A. Operaciones o transacciones a través de intermediarios que presenten conflicto de intereses. B. Intermediarios que hayan sido sancionados o no cumplan con estas normas para la AR LC/FT/FPADM | E13: R02 | F13: 1a.Tipo de EIPP | G13: Alto | H13: 5 | I13: Ocasional | J13: 2 | K13: Cumplimiento | L13: Registro inapropiado de documentos que comprueben la realización de operaciones y relaciones comerciales entre clientes y/ usuarios, ocasionando posibles incumplimientos, sanciones, pérdidas comerciales y daños reputacionales. | M13: PCLCFT02 | N13: Vigente | O13: Cada vez que ingrese un nuevo cliente, el Oficial de Cumplimiento de acuerdo con lo establecido en la LOCLDOFT (Art 10), deben velar por la completitud de los siguientes formularios: -Ficha del cliente actualizada -Documentos consignados por el cliente -Clasificación de su perfil de riesgo -Verificación de antecedentes en las listas de verificación (ONU,OFAC).
A14: =A13+1 -> 4 | B14: PCLCFT. 02 Estructura | C14: Capítulo II. Sistema Integrado de Administración de Riesgos relacionados con delitos de Legitimación de Capitales, Financiamiento al Terrorismo, Financiamiento de la Proliferación de Armas de Destrucción Masiva (LC/FT/FPADM) y otros Ilícitos. | D14: Artículo 15: Conformación del SIAR LCFTFPADM: 1. La Junta Directiva o el Órgano que ejerza fundan equivalente; 2. El presidente del sujeto obligado que ejerza función equivalente. 3. El oficial de cumplimiento. 4. La Unidad de AR LC/FI'/FPADM v Otros Ilícitos; 5. El Responsable de Cumplimiento designado en cada área sensible de riesgo 6. Los Responsables de primera línea de contacto. | E14: R03 | F14: Estructura | G14: Alto | H14: 4 | I14: Moderado | J14: 3 | K14: Cumplimiento | L14: Ausencia de un SIAR LCTFPADM según lo establecido en el Art 15 que vele por el cumplimiento de la normativa y que conste de instrumentos, procedimientos, mecanismos y sistema de gestión de riesgos adecuado. | M14: PCLCFT03 | N14: Sugerido | O14: El SIAR LCFTFPADM se encuentra debidamente conformado y aprobado por JD, todos los miembros están debidamente capacitados para dar cumplimiento a la legislación vigente.
A15: =A14+1 -> 5 | B15: PCLCFT. 02 Estructura | C15: Capítulo III. Estructura Funcional de riesgos relacionados con LC/FT/FPADM y Otros Ilícitos. Sección II | D15: Artículo 17.- El presidente o quien haga sus veces en la estructura del sujeto obligado, debe cumplir las siguientes obligaciones: 7. Informar a la SUNAVAL la postulación, renuncia y ausencia del Oficial de Cumplimiento dentro de un lapso de quince (15) días hábiles siguientes a la fecha de su nombramiento en acta de JD, así como la declaración jurada en la que manifieste el ejercicio de sus funciones en dedicación exclusiva... 9. Informar a la SUNAVAL sobre la designación de los integrantes de la UAR LC/FT/FPAMD y Otros Ilícitos dentro de un lapso de quince (15) días hábiles siguientes a la fecha de su nombramiento... | E15: R04 | F15: Estructura | G15: Medio | H15: 3 | I15: Ocasional | J15: 2 | K15: Cumplimiento | L15: Incumplimiento de los tiempos de comunicación a la SUNAVAL de los designados responsables de las funciones de Oficial de Cumplimiento y de la UAR LC/FT/FPADM) dentro de los lapsos establecidos en la legislación vigente. | M15: PCLCFT04 | N15: Sugerido | O15: Preparación y envío de comunicaciones a la SUNAVAL dentro de los plazos establecidos, realizando las remisiones de forma oportuna conforme a la norma.
A16: =A15+1 -> 6 | B16: PCLCFT. 02 Estructura | C16: Capítulo III. Estructura Funcional de riesgos relacionados con LC/FT/FPADM y Otros Ilícitos. Sección III | D16: Artículo 18 OC: Empleado de alto nivel jerárquico, de comprobada honorabilidad, con poder de decisión, que dependa y reporte directamente a la junta directiva dedicado de manera exclusiva a las funciones de AR/LC/FT/FPADM. Artículo 19. Requisitos del OC: 1. Poseer tímalo de educación superior o técnico afín con el sector del mercado de valores; 3. Acreditar mediante credenciales académicas de formación como experto en AR LC/FT/FPADM y Otros Ilícitos, en el sector de mercado de valores. 4. Estar inscrito en el registro de oficiales de cumplimiento, que lleva el órgano rector en la materia. 5. Presentar la declaración jurada en la que manifesté que ejercerá sus funciones a dedicación exclusiva. | E16: R05 | F16: Estructura | G16: Medio | H16: 3 | I16: Moderado | J16: 3 | K16: Cumplimiento | L16: Ausencia de una adecuada y comprobada formación, preparación y reputación del Oficial de Cumplimiento acorde a los requisitos establecidos en el Art 19 de la Providencia 209. | M16: PCLCFT05 | N16: Sugerido | O16: El oficial de cumplimiento designado por la JD según lo establecido en la providencia 209, art 18. posee las credenciales que avalan su debida preparación para el correcto desempeño de sus funciones de manera exclusiva y está debidamente registrado ante el ente regulador. Así mismo ha sido firmada la declaración jurada donde manifiesta el compromiso para llevar a cabo sus funciones con responsabilidad y honorabilidad.
A17: =A16+1 -> 7 | B17: PCLCFT. 02 Estructura | C17: Capítulo III. Estructura Funcional de riesgos relacionados con LC/FT/FPADM y Otros Ilícitos. Sección IV | D17: UAR LC/FT/FPAMD Artículo 22. -Es el órgano técnico operativo del sujeto obligado, a cargo de una persona de reconocida condición ética y moral, que posea título de educación superior o técnico, con experiencia o conocimiento de los productos… Artículo 23.- Conformación de la unidad Artículo 24.- Obligaciones del Gerente de la unidad Artículo 25.- Obligaciones del Analista de la unidad | E17: R06 | F17: Estructura | G17: Medio | H17: 4 | I17: Ocasional | J17: 2 | K17: Cumplimiento | L17: Inexistencia de un órgano técnico operativo (UAR LCFTFPADM) con experiencia y conocimiento de los procesos, productos y servicios del mercado de valores y de AR LCFTFPADM y otros ilícitos acorde con lo establecido en los Art 22, 23,24 y 25 de la legislación vigente. | M17: PCLCFT06 | N17: Sugerido | O17: Según lo establecido en la providencia 209, se ha conformado la UAR, con Un (1) Gerente y Un (1) Analista considerando sus funciones dentro de la estructura
A18: =A17+1 -> 8 | B18: PCLCFT. 02 Estructura | C18: Capítulo III. Estructura Funcional de riesgos relacionados con LC/FT/FPADM y Otros Ilícitos. Sección V | D18: Artículo 27: El responsable de cumplimiento tendrá las siguientes funciones: 1.Servir de enlace con el oficial de cumplimiento y prestarle apoyo en las labores de AR LC/FT/FPADM y Otros Ilícitos, en cada una de sus áreas de responsabilidad; 2. Aplicar y supervisar las providencias, políticas y procedimientos de AR 1C/FT/FPADM y Otros Ilícitos, en cada una de sus áreas de su responsabilidad; 3. Asesorar y apoyar al personal de su área de responsabilidad, en lo relacionado a los procedimientos de AR LC/FT/FPADM y Otros Ilícitos; 4. Elaborar sus respectivos planes anuales de seguimiento, evaluación y supervisión de administración de riesgos, que serán aplicados para asegurarse que sus funciones en la AR LC/FT/FPADM y Otros Ilícitos, se estén cumpliendo adecuadamente; 5. Otras estrictamente relacionadas con la AR LC/FT/FPADM y Otros Ilícitos, señaladas por el oficial de cumplimiento, la junta directiva del sujeto obligado o la Superintendencia Nacional de Valores. | E18: R07 | F18: Estructura | G18: Medio | H18: 4 | I18: Ocasional | J18: 2 | K18: Cumplimiento | L18: Ausencia de la asignación de Responsables de cumplimiento por áreas de riesgo que lleven a cabo las funciones de enlace con el OF, así como la supervisión, asesoría, apoyo, evaluación y seguimiento a los procedimientos relacionados con la AR LCFTFPADM. | M18: PCLCFT07 | N18: Vigente | O18: Se encuentran debidamente designados y aprobados por el SIAR Responsables de cumplimiento por cada área de riesgo identificada en la organización, -Consultoría Jurídica -Tecnología -Negocios -Contabilidad -Tesorería -RRHH -Mesas de Operaciones Bursátiles
